[2023-02-26 15:04:02,987] {taskinstance.py:1159} INFO - Dependencies all met for <TaskInstance: get_taxi_availability.taxi_api_to_db manual__2023-02-26T15:03:29.758151+00:00 [queued]>
[2023-02-26 15:04:02,995] {taskinstance.py:1159} INFO - Dependencies all met for <TaskInstance: get_taxi_availability.taxi_api_to_db manual__2023-02-26T15:03:29.758151+00:00 [queued]>
[2023-02-26 15:04:02,995] {taskinstance.py:1356} INFO - 
--------------------------------------------------------------------------------
[2023-02-26 15:04:02,996] {taskinstance.py:1357} INFO - Starting attempt 2 of 3
[2023-02-26 15:04:02,996] {taskinstance.py:1358} INFO - 
--------------------------------------------------------------------------------
[2023-02-26 15:04:03,007] {taskinstance.py:1377} INFO - Executing <Task(PythonOperator): taxi_api_to_db> on 2023-02-26 15:03:29.758151+00:00
[2023-02-26 15:04:03,012] {standard_task_runner.py:52} INFO - Started process 7352 to run task
[2023-02-26 15:04:03,015] {standard_task_runner.py:79} INFO - Running: ['***', 'tasks', 'run', 'get_taxi_availability', 'taxi_api_to_db', 'manual__2023-02-26T15:03:29.758151+00:00', '--job-id', '48', '--raw', '--subdir', 'DAGS_FOLDER/get_taxi_availability.py', '--cfg-path', '/tmp/tmp2q5qgp7r', '--error-file', '/tmp/tmpy90r5y0x']
[2023-02-26 15:04:03,016] {standard_task_runner.py:80} INFO - Job 48: Subtask taxi_api_to_db
[2023-02-26 15:04:03,058] {task_command.py:370} INFO - Running <TaskInstance: get_taxi_availability.taxi_api_to_db manual__2023-02-26T15:03:29.758151+00:00 [running]> on host 0337baec7fd8
[2023-02-26 15:04:03,112] {taskinstance.py:1571} INFO - Exporting the following env vars:
AIRFLOW_CTX_DAG_OWNER=***
AIRFLOW_CTX_DAG_ID=get_taxi_availability
AIRFLOW_CTX_TASK_ID=taxi_api_to_db
AIRFLOW_CTX_EXECUTION_DATE=2023-02-26T15:03:29.758151+00:00
AIRFLOW_CTX_TRY_NUMBER=2
AIRFLOW_CTX_DAG_RUN_ID=manual__2023-02-26T15:03:29.758151+00:00
[2023-02-26 15:04:04,466] {logging_mixin.py:115} INFO - Succesful connection with API.
[2023-02-26 15:04:04,467] {logging_mixin.py:115} INFO - -------------------------------
[2023-02-26 15:04:04,476] {warnings.py:110} WARNING - /opt/***/dags/functions/taxi_availability.py:51: FutureWarning: The default value of regex will change from True to False in a future version.
  df['features'] = df['features'].str.replace('"[',"''[")

[2023-02-26 15:04:04,476] {taskinstance.py:1889} ERROR - Task failed with exception
Traceback (most recent call last):
  File "/home/airflow/.local/lib/python3.7/site-packages/airflow/operators/python.py", line 171, in execute
    return_value = self.execute_callable()
  File "/home/airflow/.local/lib/python3.7/site-packages/airflow/operators/python.py", line 189, in execute_callable
    return self.python_callable(*self.op_args, **self.op_kwargs)
  File "/opt/airflow/dags/functions/taxi_availability.py", line 76, in run_taxi_api_to_db
    etl.transform()
  File "/opt/airflow/dags/functions/taxi_availability.py", line 51, in transform
    df['features'] = df['features'].str.replace('"[',"''[")
  File "/home/airflow/.local/lib/python3.7/site-packages/pandas/core/strings/accessor.py", line 116, in wrapper
    return func(self, *args, **kwargs)
  File "/home/airflow/.local/lib/python3.7/site-packages/pandas/core/strings/accessor.py", line 1402, in replace
    pat, repl, n=n, case=case, flags=flags, regex=regex
  File "/home/airflow/.local/lib/python3.7/site-packages/pandas/core/strings/object_array.py", line 156, in _str_replace
    pat = re.compile(pat, flags=flags)
  File "/usr/local/lib/python3.7/re.py", line 236, in compile
    return _compile(pattern, flags)
  File "/usr/local/lib/python3.7/re.py", line 288, in _compile
    p = sre_compile.compile(pattern, flags)
  File "/usr/local/lib/python3.7/sre_compile.py", line 764, in compile
    p = sre_parse.parse(p, flags)
  File "/usr/local/lib/python3.7/sre_parse.py", line 924, in parse
    p = _parse_sub(source, pattern, flags & SRE_FLAG_VERBOSE, 0)
  File "/usr/local/lib/python3.7/sre_parse.py", line 420, in _parse_sub
    not nested and not items))
  File "/usr/local/lib/python3.7/sre_parse.py", line 526, in _parse
    source.tell() - here)
re.error: unterminated character set at position 1
[2023-02-26 15:04:04,484] {taskinstance.py:1400} INFO - Marking task as UP_FOR_RETRY. dag_id=get_taxi_availability, task_id=taxi_api_to_db, execution_date=20230226T150329, start_date=20230226T150402, end_date=20230226T150404
[2023-02-26 15:04:04,493] {standard_task_runner.py:97} ERROR - Failed to execute job 48 for task taxi_api_to_db (unterminated character set at position 1; 7352)
[2023-02-26 15:04:04,514] {local_task_job.py:156} INFO - Task exited with return code 1
[2023-02-26 15:04:04,548] {local_task_job.py:273} INFO - 0 downstream tasks scheduled from follow-on schedule check
