[2023-02-26 14:50:16,767] {taskinstance.py:1159} INFO - Dependencies all met for <TaskInstance: get_taxi_availability.taxi_api_to_db manual__2023-02-26T14:49:12.075821+00:00 [queued]>
[2023-02-26 14:50:16,774] {taskinstance.py:1159} INFO - Dependencies all met for <TaskInstance: get_taxi_availability.taxi_api_to_db manual__2023-02-26T14:49:12.075821+00:00 [queued]>
[2023-02-26 14:50:16,775] {taskinstance.py:1356} INFO - 
--------------------------------------------------------------------------------
[2023-02-26 14:50:16,775] {taskinstance.py:1357} INFO - Starting attempt 3 of 3
[2023-02-26 14:50:16,776] {taskinstance.py:1358} INFO - 
--------------------------------------------------------------------------------
[2023-02-26 14:50:16,788] {taskinstance.py:1377} INFO - Executing <Task(PythonOperator): taxi_api_to_db> on 2023-02-26 14:49:12.075821+00:00
[2023-02-26 14:50:16,793] {standard_task_runner.py:52} INFO - Started process 6624 to run task
[2023-02-26 14:50:16,795] {standard_task_runner.py:79} INFO - Running: ['***', 'tasks', 'run', 'get_taxi_availability', 'taxi_api_to_db', 'manual__2023-02-26T14:49:12.075821+00:00', '--job-id', '28', '--raw', '--subdir', 'DAGS_FOLDER/get_taxi_availability.py', '--cfg-path', '/tmp/tmpfstu4p8_', '--error-file', '/tmp/tmp3exeru1a']
[2023-02-26 14:50:16,796] {standard_task_runner.py:80} INFO - Job 28: Subtask taxi_api_to_db
[2023-02-26 14:50:16,839] {task_command.py:370} INFO - Running <TaskInstance: get_taxi_availability.taxi_api_to_db manual__2023-02-26T14:49:12.075821+00:00 [running]> on host 0337baec7fd8
[2023-02-26 14:50:16,891] {taskinstance.py:1571} INFO - Exporting the following env vars:
AIRFLOW_CTX_DAG_OWNER=***
AIRFLOW_CTX_DAG_ID=get_taxi_availability
AIRFLOW_CTX_TASK_ID=taxi_api_to_db
AIRFLOW_CTX_EXECUTION_DATE=2023-02-26T14:49:12.075821+00:00
AIRFLOW_CTX_TRY_NUMBER=3
AIRFLOW_CTX_DAG_RUN_ID=manual__2023-02-26T14:49:12.075821+00:00
[2023-02-26 14:50:17,584] {logging_mixin.py:115} INFO - Succesful connection with API.
[2023-02-26 14:50:17,585] {logging_mixin.py:115} INFO - -------------------------------
[2023-02-26 14:50:17,604] {taskinstance.py:1889} ERROR - Task failed with exception
Traceback (most recent call last):
  File "/home/airflow/.local/lib/python3.7/site-packages/airflow/operators/python.py", line 171, in execute
    return_value = self.execute_callable()
  File "/home/airflow/.local/lib/python3.7/site-packages/airflow/operators/python.py", line 189, in execute_callable
    return self.python_callable(*self.op_args, **self.op_kwargs)
  File "/opt/airflow/dags/functions/taxi_availability.py", line 69, in run_taxi_api_to_db
    db1.run(query)
  File "/home/airflow/.local/lib/python3.7/site-packages/airflow/hooks/dbapi.py", line 186, in run
    with closing(self.get_conn()) as conn:
  File "/home/airflow/.local/lib/python3.7/site-packages/airflow/providers/postgres/hooks/postgres.py", line 86, in get_conn
    conn = deepcopy(self.connection or self.get_connection(conn_id))
  File "/home/airflow/.local/lib/python3.7/site-packages/airflow/hooks/base.py", line 67, in get_connection
    conn = Connection.get_connection_from_secrets(conn_id)
  File "/home/airflow/.local/lib/python3.7/site-packages/airflow/models/connection.py", line 430, in get_connection_from_secrets
    raise AirflowNotFoundException(f"The conn_id `{conn_id}` isn't defined")
airflow.exceptions.AirflowNotFoundException: The conn_id `postgres_default` isn't defined
[2023-02-26 14:50:17,609] {taskinstance.py:1400} INFO - Marking task as FAILED. dag_id=get_taxi_availability, task_id=taxi_api_to_db, execution_date=20230226T144912, start_date=20230226T145016, end_date=20230226T145017
[2023-02-26 14:50:17,618] {standard_task_runner.py:97} ERROR - Failed to execute job 28 for task taxi_api_to_db (The conn_id `postgres_default` isn't defined; 6624)
[2023-02-26 14:50:17,651] {local_task_job.py:156} INFO - Task exited with return code 1
[2023-02-26 14:50:17,680] {local_task_job.py:273} INFO - 0 downstream tasks scheduled from follow-on schedule check
