[2023-02-26 14:49:02,544] {taskinstance.py:1159} INFO - Dependencies all met for <TaskInstance: get_taxi_availability.taxi_api_to_db manual__2023-02-26T14:47:57.505866+00:00 [queued]>
[2023-02-26 14:49:02,553] {taskinstance.py:1159} INFO - Dependencies all met for <TaskInstance: get_taxi_availability.taxi_api_to_db manual__2023-02-26T14:47:57.505866+00:00 [queued]>
[2023-02-26 14:49:02,554] {taskinstance.py:1356} INFO - 
--------------------------------------------------------------------------------
[2023-02-26 14:49:02,554] {taskinstance.py:1357} INFO - Starting attempt 3 of 3
[2023-02-26 14:49:02,555] {taskinstance.py:1358} INFO - 
--------------------------------------------------------------------------------
[2023-02-26 14:49:02,570] {taskinstance.py:1377} INFO - Executing <Task(PythonOperator): taxi_api_to_db> on 2023-02-26 14:47:57.505866+00:00
[2023-02-26 14:49:02,575] {standard_task_runner.py:52} INFO - Started process 6558 to run task
[2023-02-26 14:49:02,577] {standard_task_runner.py:79} INFO - Running: ['***', 'tasks', 'run', 'get_taxi_availability', 'taxi_api_to_db', 'manual__2023-02-26T14:47:57.505866+00:00', '--job-id', '24', '--raw', '--subdir', 'DAGS_FOLDER/get_taxi_availability.py', '--cfg-path', '/tmp/tmpjg7yq3k8', '--error-file', '/tmp/tmpzukb5hat']
[2023-02-26 14:49:02,578] {standard_task_runner.py:80} INFO - Job 24: Subtask taxi_api_to_db
[2023-02-26 14:49:02,697] {task_command.py:370} INFO - Running <TaskInstance: get_taxi_availability.taxi_api_to_db manual__2023-02-26T14:47:57.505866+00:00 [running]> on host 0337baec7fd8
[2023-02-26 14:49:02,756] {taskinstance.py:1571} INFO - Exporting the following env vars:
AIRFLOW_CTX_DAG_OWNER=***
AIRFLOW_CTX_DAG_ID=get_taxi_availability
AIRFLOW_CTX_TASK_ID=taxi_api_to_db
AIRFLOW_CTX_EXECUTION_DATE=2023-02-26T14:47:57.505866+00:00
AIRFLOW_CTX_TRY_NUMBER=3
AIRFLOW_CTX_DAG_RUN_ID=manual__2023-02-26T14:47:57.505866+00:00
[2023-02-26 14:49:03,709] {taskinstance.py:1889} ERROR - Task failed with exception
Traceback (most recent call last):
  File "/home/airflow/.local/lib/python3.7/site-packages/airflow/operators/python.py", line 171, in execute
    return_value = self.execute_callable()
  File "/home/airflow/.local/lib/python3.7/site-packages/airflow/operators/python.py", line 189, in execute_callable
    return self.python_callable(*self.op_args, **self.op_kwargs)
  File "/opt/airflow/dags/functions/taxi_availability.py", line 93, in run_taxi_api_to_db
    db1.run(query)
  File "/home/airflow/.local/lib/python3.7/site-packages/airflow/hooks/dbapi.py", line 186, in run
    with closing(self.get_conn()) as conn:
  File "/home/airflow/.local/lib/python3.7/site-packages/airflow/providers/postgres/hooks/postgres.py", line 86, in get_conn
    conn = deepcopy(self.connection or self.get_connection(conn_id))
  File "/home/airflow/.local/lib/python3.7/site-packages/airflow/hooks/base.py", line 67, in get_connection
    conn = Connection.get_connection_from_secrets(conn_id)
  File "/home/airflow/.local/lib/python3.7/site-packages/airflow/models/connection.py", line 430, in get_connection_from_secrets
    raise AirflowNotFoundException(f"The conn_id `{conn_id}` isn't defined")
airflow.exceptions.AirflowNotFoundException: The conn_id `postgres_default` isn't defined
[2023-02-26 14:49:03,715] {taskinstance.py:1400} INFO - Marking task as FAILED. dag_id=get_taxi_availability, task_id=taxi_api_to_db, execution_date=20230226T144757, start_date=20230226T144902, end_date=20230226T144903
[2023-02-26 14:49:03,725] {standard_task_runner.py:97} ERROR - Failed to execute job 24 for task taxi_api_to_db (The conn_id `postgres_default` isn't defined; 6558)
[2023-02-26 14:49:03,756] {local_task_job.py:156} INFO - Task exited with return code 1
[2023-02-26 14:49:03,789] {local_task_job.py:273} INFO - 0 downstream tasks scheduled from follow-on schedule check
