[2023-02-27 18:17:02,415] {taskinstance.py:1159} INFO - Dependencies all met for <TaskInstance: get_taxi_availability.taxi_api_to_db scheduled__2023-02-27T18:16:00+00:00 [queued]>
[2023-02-27 18:17:02,421] {taskinstance.py:1159} INFO - Dependencies all met for <TaskInstance: get_taxi_availability.taxi_api_to_db scheduled__2023-02-27T18:16:00+00:00 [queued]>
[2023-02-27 18:17:02,421] {taskinstance.py:1356} INFO - 
--------------------------------------------------------------------------------
[2023-02-27 18:17:02,421] {taskinstance.py:1357} INFO - Starting attempt 1 of 3
[2023-02-27 18:17:02,421] {taskinstance.py:1358} INFO - 
--------------------------------------------------------------------------------
[2023-02-27 18:17:02,431] {taskinstance.py:1377} INFO - Executing <Task(PythonOperator): taxi_api_to_db> on 2023-02-27 18:16:00+00:00
[2023-02-27 18:17:02,435] {standard_task_runner.py:52} INFO - Started process 15559 to run task
[2023-02-27 18:17:02,437] {standard_task_runner.py:79} INFO - Running: ['***', 'tasks', 'run', 'get_taxi_availability', 'taxi_api_to_db', 'scheduled__2023-02-27T18:16:00+00:00', '--job-id', '707', '--raw', '--subdir', 'DAGS_FOLDER/get_taxi_availability.py', '--cfg-path', '/tmp/tmpiqn8219z', '--error-file', '/tmp/tmp9cznzosp']
[2023-02-27 18:17:02,437] {standard_task_runner.py:80} INFO - Job 707: Subtask taxi_api_to_db
[2023-02-27 18:17:02,446] {warnings.py:110} WARNING - /home/***/.local/lib/python3.7/site-packages/***/configuration.py:525: DeprecationWarning: The sql_alchemy_conn option in [core] has been moved to the sql_alchemy_conn option in [database] - the old setting has been used, but please update your config.
  option = self._get_environment_variables(deprecated_key, deprecated_section, key, section)

[2023-02-27 18:17:02,475] {task_command.py:370} INFO - Running <TaskInstance: get_taxi_availability.taxi_api_to_db scheduled__2023-02-27T18:16:00+00:00 [running]> on host d122b1b9ada0
[2023-02-27 18:17:02,525] {taskinstance.py:1571} INFO - Exporting the following env vars:
AIRFLOW_CTX_DAG_OWNER=***
AIRFLOW_CTX_DAG_ID=get_taxi_availability
AIRFLOW_CTX_TASK_ID=taxi_api_to_db
AIRFLOW_CTX_EXECUTION_DATE=2023-02-27T18:16:00+00:00
AIRFLOW_CTX_TRY_NUMBER=1
AIRFLOW_CTX_DAG_RUN_ID=scheduled__2023-02-27T18:16:00+00:00
[2023-02-27 18:17:02,531] {taskinstance.py:1889} ERROR - Task failed with exception
Traceback (most recent call last):
  File "/home/airflow/.local/lib/python3.7/site-packages/urllib3/connection.py", line 175, in _new_conn
    (self._dns_host, self.port), self.timeout, **extra_kw
  File "/home/airflow/.local/lib/python3.7/site-packages/urllib3/util/connection.py", line 72, in create_connection
    for res in socket.getaddrinfo(host, port, family, socket.SOCK_STREAM):
  File "/usr/local/lib/python3.7/socket.py", line 752, in getaddrinfo
    for res in _socket.getaddrinfo(host, port, family, type, proto, flags):
socket.gaierror: [Errno -2] Name or service not known

During handling of the above exception, another exception occurred:

Traceback (most recent call last):
  File "/home/airflow/.local/lib/python3.7/site-packages/urllib3/connectionpool.py", line 710, in urlopen
    chunked=chunked,
  File "/home/airflow/.local/lib/python3.7/site-packages/urllib3/connectionpool.py", line 386, in _make_request
    self._validate_conn(conn)
  File "/home/airflow/.local/lib/python3.7/site-packages/urllib3/connectionpool.py", line 1040, in _validate_conn
    conn.connect()
  File "/home/airflow/.local/lib/python3.7/site-packages/urllib3/connection.py", line 358, in connect
    self.sock = conn = self._new_conn()
  File "/home/airflow/.local/lib/python3.7/site-packages/urllib3/connection.py", line 187, in _new_conn
    self, "Failed to establish a new connection: %s" % e
urllib3.exceptions.NewConnectionError: <urllib3.connection.HTTPSConnection object at 0x7ff5b8bfe050>: Failed to establish a new connection: [Errno -2] Name or service not known

During handling of the above exception, another exception occurred:

Traceback (most recent call last):
  File "/home/airflow/.local/lib/python3.7/site-packages/requests/adapters.py", line 450, in send
    timeout=timeout
  File "/home/airflow/.local/lib/python3.7/site-packages/urllib3/connectionpool.py", line 786, in urlopen
    method, url, error=e, _pool=self, _stacktrace=sys.exc_info()[2]
  File "/home/airflow/.local/lib/python3.7/site-packages/urllib3/util/retry.py", line 592, in increment
    raise MaxRetryError(_pool, url, error or ResponseError(cause))
urllib3.exceptions.MaxRetryError: HTTPSConnectionPool(host='api.data.gov.sg', port=443): Max retries exceeded with url: /v1/transport/taxi-availability (Caused by NewConnectionError('<urllib3.connection.HTTPSConnection object at 0x7ff5b8bfe050>: Failed to establish a new connection: [Errno -2] Name or service not known'))

During handling of the above exception, another exception occurred:

Traceback (most recent call last):
  File "/home/airflow/.local/lib/python3.7/site-packages/airflow/operators/python.py", line 171, in execute
    return_value = self.execute_callable()
  File "/home/airflow/.local/lib/python3.7/site-packages/airflow/operators/python.py", line 189, in execute_callable
    return self.python_callable(*self.op_args, **self.op_kwargs)
  File "/opt/airflow/dags/functions/taxi_availability.py", line 95, in run_taxi_api_to_db
    etl.read_api()
  File "/opt/airflow/dags/functions/taxi_availability.py", line 25, in read_api
    response = requests.get(self.api_conn)
  File "/home/airflow/.local/lib/python3.7/site-packages/requests/api.py", line 75, in get
    return request('get', url, params=params, **kwargs)
  File "/home/airflow/.local/lib/python3.7/site-packages/requests/api.py", line 61, in request
    return session.request(method=method, url=url, **kwargs)
  File "/home/airflow/.local/lib/python3.7/site-packages/requests/sessions.py", line 529, in request
    resp = self.send(prep, **send_kwargs)
  File "/home/airflow/.local/lib/python3.7/site-packages/requests/sessions.py", line 645, in send
    r = adapter.send(request, **kwargs)
  File "/home/airflow/.local/lib/python3.7/site-packages/requests/adapters.py", line 519, in send
    raise ConnectionError(e, request=request)
requests.exceptions.ConnectionError: HTTPSConnectionPool(host='api.data.gov.sg', port=443): Max retries exceeded with url: /v1/transport/taxi-availability (Caused by NewConnectionError('<urllib3.connection.HTTPSConnection object at 0x7ff5b8bfe050>: Failed to establish a new connection: [Errno -2] Name or service not known'))
[2023-02-27 18:17:02,540] {taskinstance.py:1400} INFO - Marking task as UP_FOR_RETRY. dag_id=get_taxi_availability, task_id=taxi_api_to_db, execution_date=20230227T181600, start_date=20230227T181702, end_date=20230227T181702
[2023-02-27 18:17:02,548] {standard_task_runner.py:97} ERROR - Failed to execute job 707 for task taxi_api_to_db (HTTPSConnectionPool(host='api.data.gov.sg', port=443): Max retries exceeded with url: /v1/transport/taxi-availability (Caused by NewConnectionError('<urllib3.connection.HTTPSConnection object at 0x7ff5b8bfe050>: Failed to establish a new connection: [Errno -2] Name or service not known')); 15559)
[2023-02-27 18:17:02,570] {local_task_job.py:156} INFO - Task exited with return code 1
[2023-02-27 18:17:02,595] {local_task_job.py:273} INFO - 0 downstream tasks scheduled from follow-on schedule check
