[2023-02-26 14:45:02,089] {taskinstance.py:1159} INFO - Dependencies all met for <TaskInstance: get_taxi_availability.taxi_api_to_db scheduled__2023-02-26T14:42:00+00:00 [queued]>
[2023-02-26 14:45:02,096] {taskinstance.py:1159} INFO - Dependencies all met for <TaskInstance: get_taxi_availability.taxi_api_to_db scheduled__2023-02-26T14:42:00+00:00 [queued]>
[2023-02-26 14:45:02,096] {taskinstance.py:1356} INFO - 
--------------------------------------------------------------------------------
[2023-02-26 14:45:02,097] {taskinstance.py:1357} INFO - Starting attempt 1 of 3
[2023-02-26 14:45:02,097] {taskinstance.py:1358} INFO - 
--------------------------------------------------------------------------------
[2023-02-26 14:45:02,107] {taskinstance.py:1377} INFO - Executing <Task(PythonOperator): taxi_api_to_db> on 2023-02-26 14:42:00+00:00
[2023-02-26 14:45:02,112] {standard_task_runner.py:52} INFO - Started process 6330 to run task
[2023-02-26 14:45:02,116] {standard_task_runner.py:79} INFO - Running: ['***', 'tasks', 'run', 'get_taxi_availability', 'taxi_api_to_db', 'scheduled__2023-02-26T14:42:00+00:00', '--job-id', '14', '--raw', '--subdir', 'DAGS_FOLDER/get_taxi_availability.py', '--cfg-path', '/tmp/tmpggjysg_b', '--error-file', '/tmp/tmpuzj4_dqw']
[2023-02-26 14:45:02,117] {standard_task_runner.py:80} INFO - Job 14: Subtask taxi_api_to_db
[2023-02-26 14:45:02,186] {warnings.py:110} WARNING - /home/***/.local/lib/python3.7/site-packages/***/configuration.py:525: DeprecationWarning: The sql_alchemy_conn option in [core] has been moved to the sql_alchemy_conn option in [database] - the old setting has been used, but please update your config.
  option = self._get_environment_variables(deprecated_key, deprecated_section, key, section)

[2023-02-26 14:45:02,231] {task_command.py:370} INFO - Running <TaskInstance: get_taxi_availability.taxi_api_to_db scheduled__2023-02-26T14:42:00+00:00 [running]> on host 0337baec7fd8
[2023-02-26 14:45:02,288] {taskinstance.py:1571} INFO - Exporting the following env vars:
AIRFLOW_CTX_DAG_OWNER=***
AIRFLOW_CTX_DAG_ID=get_taxi_availability
AIRFLOW_CTX_TASK_ID=taxi_api_to_db
AIRFLOW_CTX_EXECUTION_DATE=2023-02-26T14:42:00+00:00
AIRFLOW_CTX_TRY_NUMBER=1
AIRFLOW_CTX_DAG_RUN_ID=scheduled__2023-02-26T14:42:00+00:00
[2023-02-26 14:45:02,289] {taskinstance.py:1889} ERROR - Task failed with exception
Traceback (most recent call last):
  File "/home/airflow/.local/lib/python3.7/site-packages/airflow/operators/python.py", line 171, in execute
    return_value = self.execute_callable()
  File "/home/airflow/.local/lib/python3.7/site-packages/airflow/operators/python.py", line 189, in execute_callable
    return self.python_callable(*self.op_args, **self.op_kwargs)
  File "/opt/airflow/dags/functions/taxi_availability.py", line 69, in run_taxi_api_to_db
    etl.transform()
  File "/opt/airflow/dags/functions/taxi_availability.py", line 39, in transform
    df = self.df
AttributeError: 'TaxiReadApi' object has no attribute 'df'
[2023-02-26 14:45:02,299] {taskinstance.py:1400} INFO - Marking task as UP_FOR_RETRY. dag_id=get_taxi_availability, task_id=taxi_api_to_db, execution_date=20230226T144200, start_date=20230226T144502, end_date=20230226T144502
[2023-02-26 14:45:02,311] {standard_task_runner.py:97} ERROR - Failed to execute job 14 for task taxi_api_to_db ('TaxiReadApi' object has no attribute 'df'; 6330)
[2023-02-26 14:45:02,328] {local_task_job.py:156} INFO - Task exited with return code 1
[2023-02-26 14:45:02,360] {local_task_job.py:273} INFO - 0 downstream tasks scheduled from follow-on schedule check
