[2023-02-26 14:46:04,875] {taskinstance.py:1159} INFO - Dependencies all met for <TaskInstance: get_taxi_availability.taxi_api_to_db scheduled__2023-02-26T14:42:00+00:00 [queued]>
[2023-02-26 14:46:04,882] {taskinstance.py:1159} INFO - Dependencies all met for <TaskInstance: get_taxi_availability.taxi_api_to_db scheduled__2023-02-26T14:42:00+00:00 [queued]>
[2023-02-26 14:46:04,882] {taskinstance.py:1356} INFO - 
--------------------------------------------------------------------------------
[2023-02-26 14:46:04,882] {taskinstance.py:1357} INFO - Starting attempt 3 of 3
[2023-02-26 14:46:04,883] {taskinstance.py:1358} INFO - 
--------------------------------------------------------------------------------
[2023-02-26 14:46:04,892] {taskinstance.py:1377} INFO - Executing <Task(PythonOperator): taxi_api_to_db> on 2023-02-26 14:42:00+00:00
[2023-02-26 14:46:04,896] {standard_task_runner.py:52} INFO - Started process 6390 to run task
[2023-02-26 14:46:04,899] {standard_task_runner.py:79} INFO - Running: ['***', 'tasks', 'run', 'get_taxi_availability', 'taxi_api_to_db', 'scheduled__2023-02-26T14:42:00+00:00', '--job-id', '16', '--raw', '--subdir', 'DAGS_FOLDER/get_taxi_availability.py', '--cfg-path', '/tmp/tmpc53lwp84', '--error-file', '/tmp/tmpgpnk4go7']
[2023-02-26 14:46:04,899] {standard_task_runner.py:80} INFO - Job 16: Subtask taxi_api_to_db
[2023-02-26 14:46:04,909] {warnings.py:110} WARNING - /home/***/.local/lib/python3.7/site-packages/***/configuration.py:525: DeprecationWarning: The sql_alchemy_conn option in [core] has been moved to the sql_alchemy_conn option in [database] - the old setting has been used, but please update your config.
  option = self._get_environment_variables(deprecated_key, deprecated_section, key, section)

[2023-02-26 14:46:04,937] {task_command.py:370} INFO - Running <TaskInstance: get_taxi_availability.taxi_api_to_db scheduled__2023-02-26T14:42:00+00:00 [running]> on host 0337baec7fd8
[2023-02-26 14:46:04,991] {taskinstance.py:1571} INFO - Exporting the following env vars:
AIRFLOW_CTX_DAG_OWNER=***
AIRFLOW_CTX_DAG_ID=get_taxi_availability
AIRFLOW_CTX_TASK_ID=taxi_api_to_db
AIRFLOW_CTX_EXECUTION_DATE=2023-02-26T14:42:00+00:00
AIRFLOW_CTX_TRY_NUMBER=3
AIRFLOW_CTX_DAG_RUN_ID=scheduled__2023-02-26T14:42:00+00:00
[2023-02-26 14:46:04,992] {taskinstance.py:1889} ERROR - Task failed with exception
Traceback (most recent call last):
  File "/home/airflow/.local/lib/python3.7/site-packages/airflow/operators/python.py", line 171, in execute
    return_value = self.execute_callable()
  File "/home/airflow/.local/lib/python3.7/site-packages/airflow/operators/python.py", line 189, in execute_callable
    return self.python_callable(*self.op_args, **self.op_kwargs)
  File "/opt/airflow/dags/functions/taxi_availability.py", line 90, in run_taxi_api_to_db
    query=etl.insert_to_db()
  File "/opt/airflow/dags/functions/taxi_availability.py", line 74, in insert_to_db
    df1 = self.df
AttributeError: 'TaxiReadApi' object has no attribute 'df'
[2023-02-26 14:46:05,001] {taskinstance.py:1400} INFO - Marking task as FAILED. dag_id=get_taxi_availability, task_id=taxi_api_to_db, execution_date=20230226T144200, start_date=20230226T144604, end_date=20230226T144605
[2023-02-26 14:46:05,010] {standard_task_runner.py:97} ERROR - Failed to execute job 16 for task taxi_api_to_db ('TaxiReadApi' object has no attribute 'df'; 6390)
[2023-02-26 14:46:05,031] {local_task_job.py:156} INFO - Task exited with return code 1
[2023-02-26 14:46:05,061] {local_task_job.py:273} INFO - 0 downstream tasks scheduled from follow-on schedule check
