[2023-02-26 14:44:02,232] {taskinstance.py:1159} INFO - Dependencies all met for <TaskInstance: get_taxi_availability.taxi_api_to_db manual__2023-02-26T14:43:29.412526+00:00 [queued]>
[2023-02-26 14:44:02,242] {taskinstance.py:1159} INFO - Dependencies all met for <TaskInstance: get_taxi_availability.taxi_api_to_db manual__2023-02-26T14:43:29.412526+00:00 [queued]>
[2023-02-26 14:44:02,243] {taskinstance.py:1356} INFO - 
--------------------------------------------------------------------------------
[2023-02-26 14:44:02,243] {taskinstance.py:1357} INFO - Starting attempt 2 of 3
[2023-02-26 14:44:02,244] {taskinstance.py:1358} INFO - 
--------------------------------------------------------------------------------
[2023-02-26 14:44:02,257] {taskinstance.py:1377} INFO - Executing <Task(PythonOperator): taxi_api_to_db> on 2023-02-26 14:43:29.412526+00:00
[2023-02-26 14:44:02,263] {standard_task_runner.py:52} INFO - Started process 6279 to run task
[2023-02-26 14:44:02,266] {standard_task_runner.py:79} INFO - Running: ['***', 'tasks', 'run', 'get_taxi_availability', 'taxi_api_to_db', 'manual__2023-02-26T14:43:29.412526+00:00', '--job-id', '12', '--raw', '--subdir', 'DAGS_FOLDER/get_taxi_availability.py', '--cfg-path', '/tmp/tmp7cj5_vrz', '--error-file', '/tmp/tmprtr4tijb']
[2023-02-26 14:44:02,267] {standard_task_runner.py:80} INFO - Job 12: Subtask taxi_api_to_db
[2023-02-26 14:44:02,318] {task_command.py:370} INFO - Running <TaskInstance: get_taxi_availability.taxi_api_to_db manual__2023-02-26T14:43:29.412526+00:00 [running]> on host 0337baec7fd8
[2023-02-26 14:44:02,379] {taskinstance.py:1571} INFO - Exporting the following env vars:
AIRFLOW_CTX_DAG_OWNER=***
AIRFLOW_CTX_DAG_ID=get_taxi_availability
AIRFLOW_CTX_TASK_ID=taxi_api_to_db
AIRFLOW_CTX_EXECUTION_DATE=2023-02-26T14:43:29.412526+00:00
AIRFLOW_CTX_TRY_NUMBER=2
AIRFLOW_CTX_DAG_RUN_ID=manual__2023-02-26T14:43:29.412526+00:00
[2023-02-26 14:44:02,380] {taskinstance.py:1889} ERROR - Task failed with exception
Traceback (most recent call last):
  File "/home/airflow/.local/lib/python3.7/site-packages/airflow/operators/python.py", line 171, in execute
    return_value = self.execute_callable()
  File "/home/airflow/.local/lib/python3.7/site-packages/airflow/operators/python.py", line 189, in execute_callable
    return self.python_callable(*self.op_args, **self.op_kwargs)
  File "/opt/airflow/dags/functions/taxi_availability.py", line 69, in run_taxi_api_to_db
    etl.transform()
  File "/opt/airflow/dags/functions/taxi_availability.py", line 39, in transform
    df = self.df
AttributeError: 'TaxiReadApi' object has no attribute 'df'
[2023-02-26 14:44:02,393] {taskinstance.py:1400} INFO - Marking task as UP_FOR_RETRY. dag_id=get_taxi_availability, task_id=taxi_api_to_db, execution_date=20230226T144329, start_date=20230226T144402, end_date=20230226T144402
[2023-02-26 14:44:02,403] {standard_task_runner.py:97} ERROR - Failed to execute job 12 for task taxi_api_to_db ('TaxiReadApi' object has no attribute 'df'; 6279)
[2023-02-26 14:44:02,439] {local_task_job.py:156} INFO - Task exited with return code 1
[2023-02-26 14:44:02,467] {local_task_job.py:273} INFO - 0 downstream tasks scheduled from follow-on schedule check
